<?xml version="1.0" encoding="utf-8"?>
<!-- This URDF was automatically created by SolidWorks to URDF Exporter! Originally created by Stephen Brawner (brawner@gmail.com) 
     Commit Version: 1.6.0-4-g7f85cfe  Build Version: 1.6.7995.38578
     For more information, please see http://wiki.ros.org/sw_urdf_exporter -->
<robot
  name="maze_solver">
  <link
    name="base_link">
    <inertial>
      <origin
        xyz="5.31102203782299E-17 0.0429739467849225 1.00918561979163E-16"
        rpy="0 0 0" />
      <mass
        value="1.804" />
      <inertia
        ixx="0.0170711114421656"
        ixy="1.0598798124453E-17"
        ixz="1.169964258395E-17"
        iyy="0.0289395666666667"
        iyz="-4.47235019331738E-18"
        izz="0.0357214114421656" />
    </inertial>
    <visual>
      <origin
        xyz="0 0 0"
        rpy="0 0 0" />
      <geometry>
        <mesh
          filename="package://maze_solver/meshes/base_link.STL" />
      </geometry>
      <material
        name="">
        <color
          rgba="0.792156862745098 0.819607843137255 0.933333333333333 1" />
      </material>
    </visual>
    <collision>
      <origin
        xyz="0 0 0"
        rpy="0 0 0" />
      <geometry>
        <mesh
          filename="package://maze_solver/meshes/base_link.STL" />
      </geometry>
    </collision>
  </link>
  <link
    name="sensor_r">
    <inertial>
      <origin
        xyz="0.00167825063166785 -0.0025 0.00228459119938573"
        rpy="0 0 0" />
      <mass
        value="0.000400000000000001" />
      <inertia
        ixx="2.96666666666668E-09"
        ixy="-1.88193956686158E-25"
        ixz="-1.53800619907838E-25"
        iyy="5.46666666666668E-09"
        iyz="-6.89317177127523E-26"
        izz="4.16666666666667E-09" />
    </inertial>
    <visual>
      <origin
        xyz="0 0 0"
        rpy="0 0 0" />
      <geometry>
        <mesh
          filename="package://maze_solver/meshes/sensor_r.STL" />
      </geometry>
      <material
        name="">
        <color
          rgba="0.792156862745098 0.819607843137255 0.933333333333333 1" />
      </material>
    </visual>
    <collision>
      <origin
        xyz="0 0 0"
        rpy="0 0 0" />
      <geometry>
        <mesh
          filename="package://maze_solver/meshes/sensor_r.STL" />
      </geometry>
    </collision>
  </link>
  <joint
    name="sensor_r_joint"
    type="fixed">
    <origin
      xyz="-0.195 0.00167825063166793 0.263284591199386"
      rpy="3.14159265358979 0 -3.14" />
    <parent
      link="base_link" />
    <child
      link="sensor_r" />
    <axis
      xyz="0 0 0" />
  </joint>
  <link
    name="sensor_f">
    <inertial>
      <origin
        xyz="0.00167825063166785 0.0025 -0.00228459119938573"
        rpy="0 0 1.57" />
      <mass
        value="0.0004" />
      <inertia
        ixx="2.96666666666667E-09"
        ixy="-8.90222804304396E-27"
        ixz="-4.46391304228543E-25"
        iyy="5.46666666666667E-09"
        iyz="-2.61781266765201E-43"
        izz="4.16666666666667E-09" />
    </inertial>
    <visual>
      <origin
        xyz="0 0 0"
        rpy="0 0 0" />
      <geometry>
        <mesh
          filename="package://maze_solver/meshes/sensor_f.STL" />
      </geometry>
      <material
        name="">
        <color
          rgba="0.792156862745098 0.819607843137255 0.933333333333333 1" />
      </material>
    </visual>
    <collision>
      <origin
        xyz="0 0 0"
        rpy="0 0 0" />
      <geometry>
        <mesh
          filename="package://maze_solver/meshes/sensor_f.STL" />
      </geometry>
    </collision>
  </link>
  <joint
    name="sensor_f_joint"
    type="fixed">
    <origin
      xyz="-0.00161067072073706 -0.0249999999999999 0.256715408800614"
      rpy="3.14159265358979 0 -1.57" />
    <parent
      link="base_link" />
    <child
      link="sensor_f" />
    <axis
      xyz="0 0 0" />
  </joint>
  <link
    name="sensor_l">
    <inertial>
      <origin
        xyz="0.00167825063166785 -0.0025 0.00228459119938573"
        rpy="0 0 0" />
      <mass
        value="0.000400000000000001" />
      <inertia
        ixx="2.96666666666668E-09"
        ixy="-4.50365103748664E-25"
        ixz="6.06937399655524E-26"
        iyy="5.46666666666668E-09"
        iyz="-1.21220896784814E-25"
        izz="4.16666666666668E-09" />
    </inertial>
    <visual>
      <origin
        xyz="0 0 0"
        rpy="0 0 0" />
      <geometry>
        <mesh
          filename="package://maze_solver/meshes/sensor_l.STL" />
      </geometry>
      <material
        name="">
        <color
          rgba="0.792156862745098 0.819607843137255 0.933333333333333 1" />
      </material>
    </visual>
    <collision>
      <origin
        xyz="0 0 0"
        rpy="0 0 0" />
      <geometry>
        <mesh
          filename="package://maze_solver/meshes/sensor_l.STL" />
      </geometry>
    </collision>
  </link>
  <joint
    name="sensor_l_joint"
    type="fixed">
    <origin
      xyz="0.19 0.00167825063166787 0.261284591199386"
      rpy="3.14159265358979 0 0" />
    <parent
      link="base_link" />
    <child
      link="sensor_l" />
    <axis
      xyz="0 0 0" />
  </joint>
  <link
    name="wheel_l">
    <inertial>
      <origin
        xyz="2.60208521396521E-18 -1.73472347597681E-18 0.00500000000000003"
        rpy="0 0 0" />
      <mass
        value="0.0282743338823082" />
      <inertia
        ixx="6.59734457253857E-06"
        ixy="0"
        ixz="-2.11023447556403E-38"
        iyy="6.59734457253857E-06"
        iyz="-4.98934721673592E-39"
        izz="1.27234502470387E-05" />
    </inertial>
    <visual>
      <origin
        xyz="0 0 0"
        rpy="0 0 0" />
      <geometry>
        <mesh
          filename="package://maze_solver/meshes/wheel_l.STL" />
      </geometry>
      <material
        name="">
        <color
          rgba="0.792156862745098 0.819607843137255 0.933333333333333 1" />
      </material>
    </visual>
    <collision>
      <origin
        xyz="0 0 0"
        rpy="0 0 0" />
      <geometry>
        <mesh
          filename="package://maze_solver/meshes/wheel_l.STL" />
      </geometry>
    </collision>
  </link>
  <joint
    name="wheel_l_joint"
    type="continuous">
    <origin
      xyz="0.19 0 0.01"
      rpy="1.5707963267949 0.885460579278242 1.5707963267949" />
    <parent
      link="base_link" />
    <child
      link="wheel_l" />
    <axis
      xyz="0 0 1" />
    <limit
      lower="0"
      upper="0"
      effort="0"
      velocity="0" />
  </joint>
  <link
    name="wheel_r">
    <inertial>
      <origin
        xyz="-5.20417042793042E-18 -2.73218947466347E-17 0.005"
        rpy="0 0 0" />
      <mass
        value="0.0282743338823082" />
      <inertia
        ixx="6.59734457253857E-06"
        ixy="4.2351647362715E-22"
        ixz="-2.01218426660431E-38"
        iyy="6.59734457253857E-06"
        iyz="-1.22945901590415E-38"
        izz="1.27234502470387E-05" />
    </inertial>
    <visual>
      <origin
        xyz="0 0 0"
        rpy="0 0 0" />
      <geometry>
        <mesh
          filename="package://maze_solver/meshes/wheel_r.STL" />
      </geometry>
      <material
        name="">
        <color
          rgba="0.792156862745098 0.819607843137255 0.933333333333333 1" />
      </material>
    </visual>
    <collision>
      <origin
        xyz="0 0 0"
        rpy="0 0 0" />
      <geometry>
        <mesh
          filename="package://maze_solver/meshes/wheel_r.STL" />
      </geometry>
    </collision>
  </link>
  <joint
    name="wheel_r_joint"
    type="continuous">
    <origin
      xyz="-0.19 0 0.01"
      rpy="1.5707963267949 1.30809386854526 -1.5707963267949" />
    <parent
      link="base_link" />
    <child
      link="wheel_r" />
    <axis
      xyz="0 0 -1" />
    <limit
      lower="0"
      upper="0"
      effort="0"
      velocity="0" />
  </joint>
  <link
    name="caster_b">
    <inertial>
      <origin
        xyz="5.45392589743884E-17 -0.0069775457017438 -1.38777878078145E-17"
        rpy="0 0 0" />
      <mass
        value="0.00506672375389253" />
      <inertia
        ixx="2.64465523113008E-07"
        ixy="-2.79682351976512E-25"
        ixz="-8.00725373235536E-23"
        iyy="4.95058764494176E-07"
        iyz="-3.3989005198155E-25"
        izz="2.64465523113008E-07" />
    </inertial>
    <visual>
      <origin
        xyz="0 0 0"
        rpy="0 0 0" />
      <geometry>
        <mesh
          filename="package://maze_solver/meshes/caster_b.STL" />
      </geometry>
      <material
        name="">
        <color
          rgba="0.792156862745098 0.819607843137255 0.933333333333333 1" />
      </material>
    </visual>
    <collision>
      <origin
        xyz="0 0 0"
        rpy="0 0 0" />
      <geometry>
        <sphere radius="0.02"/>
      </geometry>
    </collision>
  </link>
  <joint
    name="caster_b_joint"
    type="continuous">
    <origin
      xyz="0 0.08625 0"
      rpy="1.5707963267949 0 0" />
    <parent
      link="base_link" />
    <child
      link="caster_b" />
  </joint>
  <link
    name="caster_f">
    <inertial>
      <origin
        xyz="4.16333634234434E-17 -0.0069775457017438 2.77555756156289E-17"
        rpy="0 0 0" />
      <mass
        value="0.00506672375389253" />
      <inertia
        ixx="2.64465523113008E-07"
        ixy="-3.17254822005274E-25"
        ixz="-3.97046694025453E-23"
        iyy="4.95058764494176E-07"
        iyz="-2.20140457848662E-24"
        izz="2.64465523113008E-07" />
    </inertial>
    <visual>
      <origin
        xyz="0 0 0"
        rpy="0 0 0" />
      <geometry>
        <mesh
          filename="package://maze_solver/meshes/caster_f.STL" />
      </geometry>
      <material
        name="">
        <color
          rgba="0.792156862745098 0.819607843137255 0.933333333333333 1" />
      </material>
    </visual>
    <collision>
      <origin
        xyz="0 0 0"
        rpy="0 0 0" />
      <geometry>
        <sphere radius="0.02"/>
      </geometry>
    </collision>
  </link>
  <joint
    name="caster_f_joint"
    type="continuous">
    <origin
      xyz="0 -0.08625 0"
      rpy="1.5707963267949 0 0.599335912665456" />
    <parent
      link="base_link" />
    <child
      link="caster_f" />
    
  </joint>
  <link
    name="arm_base">
    <inertial>
      <origin
        xyz="-0.19 0.00499999999999984 0.0249999999999999"
        rpy="0 0 0" />
      <mass
        value="0.0449400000000003" />
      <inertia
        ixx="2.1614E-05"
        ixy="-2.4818065354551E-19"
        ixz="-2.46307560799246E-19"
        iyy="0.000660992500000002"
        iyz="-1.71681721517741E-20"
        izz="0.000640127500000002" />
    </inertial>
    <visual>
      <origin
        xyz="0 0 0"
        rpy="0 0 0" />
      <geometry>
        <mesh
          filename="package://maze_solver/meshes/arm_base.STL" />
      </geometry>
      <material
        name="">
        <color
          rgba="1 1 1 0.32" />
      </material>
    </visual>
    <collision>
      <origin
        xyz="0 0 0"
        rpy="0 0 0" />
      <geometry>
        <mesh
          filename="package://maze_solver/meshes/arm_base.STL" />
      </geometry>
    </collision>
  </link>
  <joint
    name="arm_base_joint"
    type="revolute">
    <origin
      xyz="0.189999999999998 0.0250000000000001 0.265000000000002"
      rpy="1.5707963267949 0.219374105739364 0" />
    <parent
      link="base_link" />
    <child
      link="arm_base" />
    <axis
      xyz="0 0 1" />
    <limit
      lower="-0.40"
      upper="-0.40"
      effort="0"
      velocity="0" />
  </joint>
  <link
    name="arm_top">
    <inertial>
      <origin
        xyz="0.189999999999999 0.00499999999999967 0.0250000000000002"
        rpy="0 0 0" />
      <mass
        value="0.0449399999999996" />
      <inertia
        ixx="2.1614E-05"
        ixy="1.33661799076729E-18"
        ixz="7.28291543396973E-19"
        iyy="0.000660992499999993"
        iyz="-3.13769731425328E-20"
        izz="0.000640127499999993" />
    </inertial>
    <visual>
      <origin
        xyz="0 0 0"
        rpy="0 0 0" />
      <geometry>
        <mesh
          filename="package://maze_solver/meshes/arm_top.STL" />
      </geometry>
      <material
        name="">
        <color
          rgba="1 1 1 0.32" />
      </material>
    </visual>
    <collision>
      <origin
        xyz="0 0 0"
        rpy="0 0 0" />
      <geometry>
        <mesh
          filename="package://maze_solver/meshes/arm_top.STL" />
      </geometry>
    </collision>
  </link>
  <joint
    name="arm_top_joint"
    type="revolute">
    <origin
      xyz="-0.379999999999998 0.00999999999999857 0"
      rpy="0 0 0.514515495694071" />
    <parent
      link="arm_base" />
    <child
      link="arm_top" />
    <axis
      xyz="0 0 1" />
    <limit
      lower="1.63"
      upper="1.63"
      effort="0"
      velocity="0" />
  </joint>
  <link
    name="camera">
    <inertial>
      <origin
        xyz="0.0038889997713113 0.00979718551655867 -0.00334293059033772"
        rpy="0 0 0" />
      <mass
        value="0.0642" />
      <inertia
        ixx="1.5515E-05"
        ixy="1.69259430207196E-20"
        ixz="-4.53927511842652E-21"
        iyy="2.91544073556646E-05"
        iyz="-5.19518365443481E-06"
        izz="2.48805926443354E-05" />
    </inertial>
    <visual>
      <origin
        xyz="0 0 0"
        rpy="0 0 0" />
      <geometry>
        <mesh
          filename="package://maze_solver/meshes/camera.STL" />
      </geometry>
      <material
        name="">
        <color
          rgba="1 1 1 0.32" />
      </material>
    </visual>
    <collision>
      <origin
        xyz="0 0 0"
        rpy="0 0 0" />
      <geometry>
        <mesh
          filename="package://maze_solver/meshes/camera.STL" />
      </geometry>
    </collision>
  </link>
  <joint
    name="camera"
    type="fixed">
    <origin
      xyz="0.352324176953221 0.0100000000000041 0.0288889997713121"
      rpy="0 -1.57 1.57" />
    <parent
      link="arm_top" />
    <child
      link="camera" />
  </joint>
  <gazebo>
  <plugin name="differential_drive_controller" filename="libgazebo_ros_diff_drive.so">
    <alwaysOn>true</alwaysOn>
    <legacyMode>false</legacyMode>
    <updateRate>40</updateRate>
    <leftJoint>wheel_l_joint</leftJoint>
    <rightJoint>wheel_r_joint</rightJoint>
    <wheelSeparation>0.38</wheelSeparation>
    <wheelDiameter>0.06</wheelDiameter>
    <torque>100</torque>
    <commandTopic>maze_solver/cmd_vel</commandTopic>
    <odometryTopic>odom</odometryTopic>
    <odometryFrame>odom</odometryFrame>
    <robotBaseFrame>base_footprint</robotBaseFrame>
    <wheelAcceleration>1.0</wheelAcceleration>
    <publishWheelJointState>true</publishWheelJointState>
  </plugin>
</gazebo>
<gazebo reference="sensor_f">        
   			<sensor type="ray" name="sensor_f">
		      <pose>0 0 0 0 0 0</pose>
		      <visualize>true</visualize>
		      <update_rate>40</update_rate>
		      <ray>
		         <scan>
		            <horizontal>
		               <samples>10</samples>
		               <resolution>1</resolution> 
		               <min_angle>-0.05</min_angle>
		               <max_angle>0.05</max_angle>
		            </horizontal>
		            <vertical>
		               <samples>10</samples>
		               <resolution>1</resolution> 
		               <min_angle>-0</min_angle>
		               <max_angle>0</max_angle> 
		            </vertical>
		         </scan>
		         <range>
		            <min>0.01</min>
		            <max>10</max>
		            <resolution>0.02</resolution>
		         </range>
		      </ray>
		      <plugin filename="libgazebo_ros_range.so" name="gazebo_ros_range">
		         <gaussianNoise>0.005</gaussianNoise>
		         <alwaysOn>true</alwaysOn>
		         <updateRate>40</updateRate>
		         <topicName>maze_solver/sensor_f</topicName>
		         <frameName>sensor_front</frameName>
		         <radiation>INFRARED</radiation>
		         <fov>0.2967</fov>
		      </plugin>
		   	</sensor>  
   		</gazebo>
 <gazebo reference="sensor_r">        
   			<sensor type="ray" name="sensor_r">
		      <pose>0 0 0 0 0 0</pose>
		      <visualize>true</visualize>
		      <update_rate>40</update_rate>
		      <ray>
		         <scan>
		            <horizontal>
		               <samples>10</samples>
		               <resolution>1</resolution> 
		               <min_angle>-0.02</min_angle>
		               <max_angle>0.02</max_angle>
		            </horizontal>
		            <vertical>
		               <samples>10</samples>
		               <resolution>1</resolution> 
		               <min_angle>-0</min_angle>
		               <max_angle>0</max_angle> 
		            </vertical>
		         </scan>
		         <range>
		            <min>0.01</min>
		            <max>10</max>
		            <resolution>0.02</resolution>
		         </range>
		      </ray>
		      <plugin filename="libgazebo_ros_range.so" name="gazebo_ros_range">
		         <gaussianNoise>0.005</gaussianNoise>
		         <alwaysOn>true</alwaysOn>
		         <updateRate>40</updateRate>
		         <topicName>maze_solver/sensor_r</topicName>
		         <frameName>sensor_right</frameName>
		         <radiation>INFRARED</radiation>
		         <fov>0.2967</fov>
		      </plugin>
		   	</sensor>  
   		</gazebo>
      <gazebo reference="sensor_l">        
   			<sensor type="ray" name="sensor_l">
		      <pose>0 0 0 0 0 0</pose>
		      <visualize>true</visualize>
		      <update_rate>40</update_rate>
		      <ray>
		         <scan>
		            <horizontal>
		               <samples>10</samples>
		               <resolution>1</resolution> 
		               <min_angle>-0.02</min_angle>
		               <max_angle>0.02</max_angle>
		            </horizontal>
		            <vertical>
		               <samples>10</samples>
		               <resolution>1</resolution> 
		               <min_angle>-0</min_angle>
		               <max_angle>0</max_angle> 
		            </vertical>
		         </scan>
		         <range>
		            <min>0.01</min>
		            <max>10</max>
		            <resolution>0.02</resolution>
		         </range>
		      </ray>
		      <plugin filename="libgazebo_ros_range.so" name="gazebo_ros_range">
		         <gaussianNoise>0.005</gaussianNoise>
		         <alwaysOn>true</alwaysOn>
		         <updateRate>40</updateRate>
		         <topicName>maze_solver/sensor_l</topicName>
		         <frameName>sensor_left</frameName>
		         <radiation>INFRARED</radiation>
		         <fov>0.2967</fov>
		      </plugin>
		   	</sensor>  
   		</gazebo>
       <gazebo reference="camera">
    <sensor type="camera" name="camera">
      <update_rate>40.0</update_rate>
      <camera name="head">
        <horizontal_fov>1.047</horizontal_fov>
        <image>
          <width>1000</width>
          <height>800</height>
          <format>R8G8B8</format>
        </image>
        <clip>
          <near>0.02</near>
          <far>300</far>
        </clip>
        <noise>
          <type>gaussian</type>
          <!-- Noise is sampled independently per pixel on each frame.
               That pixel's noise value is added to each of its color
               channels, which at that point lie in the range [0,1]. -->
          <mean>0.0</mean>
          <stddev>0.007</stddev>
        </noise>
      </camera>
      <plugin name="camera_controller" filename="libgazebo_ros_camera.so">
        <alwaysOn>true</alwaysOn> 
        <updateRate>0.0</updateRate>          <!--not sure-->
        <cameraName>maze_solver/camera</cameraName>
        <imageTopicName>image_topic</imageTopicName>
        <cameraInfoTopicName>camera_info</cameraInfoTopicName>
        <frameName>camera_feed</frameName>
        <hackBaseline>0.07</hackBaseline>
        <distortionK1>0.0</distortionK1>
        <distortionK2>0.0</distortionK2>
        <distortionK3>0.0</distortionK3>
        <distortionT1>0.0</distortionT1>
        <distortionT2>0.0</distortionT2>
      </plugin>
    </sensor>
  </gazebo>
  <gazebo reference="wheel_l">
    <mu1>0.9</mu1>
    <mu2>0.9</mu2>
  <minDepth>0.001</minDepth>
    <kp>100000000</kp>
    <kd>1</kd>
</gazebo>
<gazebo reference="wheel_r">
    <mu1>0.9</mu1>
    <mu2>0.9</mu2>
  <minDepth>0.001</minDepth>
    <kp>1000000000</kp>
    <kd>0.5</kd>
</gazebo>
</robot>